Workbook

Sheet 🏠 Property Comparison
A1: 🏙️ DUBAI PROPERTY INVESTMENT COMPARATOR
A2: All figures in AED | Blue = inputs | Black = formulas | Dubai Land Department standard rates applied
B4: # | C4: METRIC | D4: Property 1 | E4: Property 2 | F4: Property 3 | G4: Property 4 | H4: Property 5
B5: ① PROPERTY DETAILS
B6: 1 | C6: Property Name / Description | D6: Property 1 | E6: Property 2 | F6: Property 3 | G6: Property 4 | H6: Property 5
B7: 2 | C7: Location / Community | D7: Dubai Marina | E7: Downtown | F7: JVC | G7: Palm Jumeirah | H7: Business Bay
B8: 3 | C8: Property Type | D8: Apartment | E8: Apartment | F8: Apartment | G8: Villa | H8: Apartment
B9: 4 | C9: Bedrooms | D9: 1 | E9: 2 | F9: 1 | G9: 4 | H9: 2
B10: 5 | C10: Size (sq ft) | D10: 650 | E10: 1100 | F10: 750 | G10: 3200 | H10: 900
B11: 6 | C11: Purchase Price (AED) | D11: 1200000 | E11: 2500000 | F11: 900000 | G11: 6500000 | H11: 1800000
B12: 7 | C12: Listed Price per sq ft | D12: =IFERROR($D$11/$D$10,"-") -> 1846.1538 | E12: =IFERROR($E$11/$E$10,"-") -> 2272.7273 | F12: =IFERROR($F$11/$F$10,"-") -> 1200 | G12: =IFERROR($G$11/$G$10,"-") -> 2031.25 | H12: =IFERROR($H$11/$H$10,"-") -> 2000
B13: ② ACQUISITION COSTS (One-Time)
B14: 8 | C14: DLD Transfer Fee (4% standard) | D14: 0.04 | E14: 0.04 | F14: 0.04 | G14: 0.04 | H14: 0.04
C15: ↳ DLD Fee Amount | D15: =$D$11*$D$14 -> 48000 | E15: =$E$11*$E$14 -> 100000 | F15: =$F$11*$F$14 -> 36000 | G15: =$G$11*$G$14 -> 260000 | H15: =$H$11*$H$14 -> 72000
B16: 9 | C16: Trustee Office Fee (AED) | D16: 4000 | E16: 4000 | F16: 4000 | G16: 4000 | H16: 4000
B17: 10 | C17: NOC Certificate (AED) | D17: 3000 | E17: 3000 | F17: 3000 | G17: 3000 | H17: 3000
B18: 11 | C18: Agent Commission (%) | D18: 0.02 | E18: 0.02 | F18: 0.02 | G18: 0.02 | H18: 0.02
C19: ↳ Agent Fee Amount | D19: =$D$11*$D$18 -> 24000 | E19: =$E$11*$E$18 -> 50000 | F19: =$F$11*$F$18 -> 18000 | G19: =$G$11*$G$18 -> 130000 | H19: =$H$11*$H$18 -> 36000
B20: 12 | C20: Mortgage Reg. Fee (% of loan) | D20: 0.0025 | E20: 0.0025 | F20: 0.0025 | G20: 0.0025 | H20: 0.0025
B21: 13 | C21: Loan Amount (0 if cash) | D21: 0 | E21: 0 | F21: 0 | G21: 0 | H21: 0
C22: ↳ Mortgage Reg. Fee Amount | D22: =$D$21*$D$20 -> 0 | E22: =$E$21*$E$20 -> 0 | F22: =$F$21*$F$20 -> 0 | G22: =$G$21*$G$20 -> 0 | H22: =$H$21*$H$20 -> 0
B23: 14 | C23: Property Valuation Fee | D23: 3500 | E23: 3500 | F23: 3500 | G23: 3500 | H23: 3500
B24: 15 | C24: Furnishing / Fit-Out Cost | D24: 30000 | E24: 60000 | F24: 20000 | G24: 200000 | H24: 50000
B25: 16 | C25: Other Acquisition Costs | D25: 0 | E25: 0 | F25: 0 | G25: 0 | H25: 0
B26: ∑ | C26: TOTAL ACQUISITION COSTS | D26: =$D$15+$D$16+$D$17+$D$19+$D$22+$D$23+$D$24+$D$25 -> 112500 | E26: =$E$15+$E$16+$E$17+$E$19+$E$22+$E$23+$E$24+$E$25 -> 220500 | F26: =$F$15+$F$16+$F$17+$F$19+$F$22+$F$23+$F$24+$F$25 -> 84500 | G26: =$G$15+$G$16+$G$17+$G$19+$G$22+$G$23+$G$24+$G$25 -> 600500 | H26: =$H$15+$H$16+$H$17+$H$19+$H$22+$H$23+$H$24+$H$25 -> 168500
B27: ∑ | C27: TOTAL INVESTMENT (Price + Acq.) | D27: =$D$11+$D$26 -> 1312500 | E27: =$E$11+$E$26 -> 2720500 | F27: =$F$11+$F$26 -> 984500 | G27: =$G$11+$G$26 -> 7100500 | H27: =$H$11+$H$26 -> 1968500
B28: 17 | C28: Equity / Cash Down Payment (AED) | D28: =$D$11-$D$21 -> 1200000 | E28: =$E$11-$E$21 -> 2500000 | F28: =$F$11-$F$21 -> 900000 | G28: =$G$11-$G$21 -> 6500000 | H28: =$H$11-$H$21 -> 1800000
B29: ③ ANNUAL HOLDING COSTS
B30: 18 | C30: Service Charges (AED/sqft/yr) | D30: 15 | E30: 18 | F30: 12 | G30: 22 | H30: 16
C31: ↳ Service Charge Amount | D31: =$D$30*$D$10 -> 9750 | E31: =$E$30*$E$10 -> 19800 | F31: =$F$30*$F$10 -> 9000 | G31: =$G$30*$G$10 -> 70400 | H31: =$H$30*$H$10 -> 14400
B32: 19 | C32: Property Management Fee (%) | D32: 0.08 | E32: 0.08 | F32: 0.08 | G32: 0.08 | H32: 0.08
B33: 20 | C33: Maintenance & Repairs (AED) | D33: 5000 | E33: 8000 | F33: 4000 | G33: 25000 | H33: 6000
B34: 21 | C34: Property Insurance (AED) | D34: 5000 | E34: 8000 | F34: 4000 | G34: 15000 | H34: 6000
B35: 22 | C35: DEWA / Utilities (AED, owner-paid) | D35: 0 | E35: 0 | F35: 0 | G35: 0 | H35: 0
B36: 23 | C36: Annual Mortgage Payments (AED) | D36: 0 | E36: 0 | F36: 0 | G36: 0 | H36: 0
B37: 24 | C37: Other Annual Costs (AED) | D37: 0 | E37: 0 | F37: 0 | G37: 0 | H37: 0
B38: ∑ | C38: TOTAL ANNUAL HOLDING COSTS | D38: =$D$31+$D$33+$D$34+$D$35+$D$36+$D$37 -> 19750 | E38: =$E$31+$E$33+$E$34+$E$35+$E$36+$E$37 -> 35800 | F38: =$F$31+$F$33+$F$34+$F$35+$F$36+$F$37 -> 17000 | G38: =$G$31+$G$33+$G$34+$G$35+$G$36+$G$37 -> 110400 | H38: =$H$31+$H$33+$H$34+$H$35+$H$36+$H$37 -> 26400
B39: ④ RENTAL INCOME
B40: 25 | C40: Estimated Gross Annual Rent (AED) | D40: 90000 | E40: 180000 | F40: 72000 | G40: 480000 | H40: 130000
B41: 26 | C41: Vacancy Rate (%) | D41: 0.05 | E41: 0.05 | F41: 0.08 | G41: 0.05 | H41: 0.06
...

Sheet 🏦 Mortgage Calculator
A1: 🏦 DUBAI MORTGAGE CALCULATOR & CASH vs FINANCE COMPARISON
A2: Blue = inputs | Black = formulas | Green = linked from Property Comparison | UAE/Dubai bank standards applied
C4: INPUT / METRIC | D4: 🏦 MORTGAGE ROUTE | E4: 💵 CASH ROUTE | G4: AMORTISATION SCHEDULE (Annual Summary)
C5: ① PROPERTY DETAILS — link from comparison sheet or enter manually | G5: YEAR | H5: PRINCIPAL PAID (AED) | I5: INTEREST PAID (AED)
B6: 1 | C6: Property Name | D6: My Property | E6: My Property | G6: 1 | H6: =IFERROR(IFERROR(-PPMT(D$22,((1-1)*12)+1,D$23,D$15),0)+IFERROR(-PPMT(D$22,((1-1)*12)+2,D$23,D$15),0)+IFERROR(-PPMT(D$22,((1-1)*12)+3,D$23,D$15),0)+IFERROR(-PPMT(D$22,((1-1)*12)+4,D$23,D$15),0)+IFERROR(-PPMT(D$22,((1-1)*12)+5,D$23,D$15),0)+IFERROR(-PPMT(D$22,((1-1)*12)+6,D$23,D$15),0)+IFERROR(-PPMT(D$22,((1-1)*12)+7,D$23,D$15),0)+IFERROR(-PPMT(D$22,((1-1)*12)+8,D$23,D$15),0)+IFERROR(-PPMT(D$22,((1-1)*12)+9,D$23,D$15),0)+IFERROR(-PPMT(D$22,((1-1)*12)+10,D$23,D$15),0)+IFERROR(-PPMT(D$22,((1-1)*12)+11,D$23,D$15),0)+IFERROR(-PPMT(D$22,((1-1)*12)+12,D$23,D$15),0),0) -> 26583.72 | I6: =IFERROR(IFERROR(-IPMT(D$22,((1-1)*12)+1,D$23,D$15),0)+IFERROR(-IPMT(D$22,((1-1)*12)+2,D$23,D$15),0)+IFERROR(-IPMT(D$22,((1-1)*12)+3,D$23,D$15),0)+IFERROR(-IPMT(D$22,((1-1)*12)+4,D$23,D$15),0)+IFERROR(-IPMT(D$22,((1-1)*12)+5,D$23,D$15),0)+IFERROR(-IPMT(D$22,((1-1)*12)+6,D$23,D$15),0)+IFERROR(-IPMT(D$22,((1-1)*12)+7,D$23,D$15),0)+IFERROR(-IPMT(D$22,((1-1)*12)+8,D$23,D$15),0)+IFERROR(-IPMT(D$22,((1-1)*12)+9,D$23,D$15),0)+IFERROR(-IPMT(D$22,((1-1)*12)+10,D$23,D$15),0)+IFERROR(-IPMT(D$22,((1-1)*12)+11,D$23,D$15),0)+IFERROR(-IPMT(D$22,((1-1)*12)+12,D$23,D$15),0),0) -> 53456.157
B7: 2 | C7: Purchase Price (AED) | D7: 1500000 | E7: 1500000 | G7: 2 | H7: =IFERROR(IFERROR(-PPMT(D$22,((2-1)*12)+1,D$23,D$15),0)+IFERROR(-PPMT(D$22,((2-1)*12)+2,D$23,D$15),0)+IFERROR(-PPMT(D$22,((2-1)*12)+3,D$23,D$15),0)+IFERROR(-PPMT(D$22,((2-1)*12)+4,D$23,D$15),0)+IFERROR(-PPMT(D$22,((2-1)*12)+5,D$23,D$15),0)+IFERROR(-PPMT(D$22,((2-1)*12)+6,D$23,D$15),0)+IFERROR(-PPMT(D$22,((2-1)*12)+7,D$23,D$15),0)+IFERROR(-PPMT(D$22,((2-1)*12)+8,D$23,D$15),0)+IFERROR(-PPMT(D$22,((2-1)*12)+9,D$23,D$15),0)+IFERROR(-PPMT(D$22,((2-1)*12)+10,D$23,D$15),0)+IFERROR(-PPMT(D$22,((2-1)*12)+11,D$23,D$15),0)+IFERROR(-PPMT(D$22,((2-1)*12)+12,D$23,D$15),0),0) -> 27804.971 | I7: =IFERROR(IFERROR(-IPMT(D$22,((2-1)*12)+1,D$23,D$15),0)+IFERROR(-IPMT(D$22,((2-1)*12)+2,D$23,D$15),0)+IFERROR(-IPMT(D$22,((2-1)*12)+3,D$23,D$15),0)+IFERROR(-IPMT(D$22,((2-1)*12)+4,D$23,D$15),0)+IFERROR(-IPMT(D$22,((2-1)*12)+5,D$23,D$15),0)+IFERROR(-IPMT(D$22,((2-1)*12)+6,D$23,D$15),0)+IFERROR(-IPMT(D$22,((2-1)*12)+7,D$23,D$15),0)+IFERROR(-IPMT(D$22,((2-1)*12)+8,D$23,D$15),0)+IFERROR(-IPMT(D$22,((2-1)*12)+9,D$23,D$15),0)+IFERROR(-IPMT(D$22,((2-1)*12)+10,D$23,D$15),0)+IFERROR(-IPMT(D$22,((2-1)*12)+11,D$23,D$15),0)+IFERROR(-IPMT(D$22,((2-1)*12)+12,D$23,D$15),0),0) -> 52234.906
B8: 3 | C8: Gross Annual Rent (AED) | D8: 110000 | E8: 110000 | G8: 3 | H8: =IFERROR(IFERROR(-PPMT(D$22,((3-1)*12)+1,D$23,D$15),0)+IFERROR(-PPMT(D$22,((3-1)*12)+2,D$23,D$15),0)+IFERROR(-PPMT(D$22,((3-1)*12)+3,D$23,D$15),0)+IFERROR(-PPMT(D$22,((3-1)*12)+4,D$23,D$15),0)+IFERROR(-PPMT(D$22,((3-1)*12)+5,D$23,D$15),0)+IFERROR(-PPMT(D$22,((3-1)*12)+6,D$23,D$15),0)+IFERROR(-PPMT(D$22,((3-1)*12)+7,D$23,D$15),0)+IFERROR(-PPMT(D$22,((3-1)*12)+8,D$23,D$15),0)+IFERROR(-PPMT(D$22,((3-1)*12)+9,D$23,D$15),0)+IFERROR(-PPMT(D$22,((3-1)*12)+10,D$23,D$15),0)+IFERROR(-PPMT(D$22,((3-1)*12)+11,D$23,D$15),0)+IFERROR(-PPMT(D$22,((3-1)*12)+12,D$23,D$15),0),0) -> 29082.327 | I8: =IFERROR(IFERROR(-IPMT(D$22,((3-1)*12)+1,D$23,D$15),0)+IFERROR(-IPMT(D$22,((3-1)*12)+2,D$23,D$15),0)+IFERROR(-IPMT(D$22,((3-1)*12)+3,D$23,D$15),0)+IFERROR(-IPMT(D$22,((3-1)*12)+4,D$23,D$15),0)+IFERROR(-IPMT(D$22,((3-1)*12)+5,D$23,D$15),0)+IFERROR(-IPMT(D$22,((3-1)*12)+6,D$23,D$15),0)+IFERROR(-IPMT(D$22,((3-1)*12)+7,D$23,D$15),0)+IFERROR(-IPMT(D$22,((3-1)*12)+8,D$23,D$15),0)+IFERROR(-IPMT(D$22,((3-1)*12)+9,D$23,D$15),0)+IFERROR(-IPMT(D$22,((3-1)*12)+10,D$23,D$15),0)+IFERROR(-IPMT(D$22,((3-1)*12)+11,D$23,D$15),0)+IFERROR(-IPMT(D$22,((3-1)*12)+12,D$23,D$15),0),0) -> 50957.55
B9: 4 | C9: Annual Holding Costs (AED) | D9: 35000 | E9: 35000 | G9: 4 | H9: =IFERROR(IFERROR(-PPMT(D$22,((4-1)*12)+1,D$23,D$15),0)+IFERROR(-PPMT(D$22,((4-1)*12)+2,D$23,D$15),0)+IFERROR(-PPMT(D$22,((4-1)*12)+3,D$23,D$15),0)+IFERROR(-PPMT(D$22,((4-1)*12)+4,D$23,D$15),0)+IFERROR(-PPMT(D$22,((4-1)*12)+5,D$23,D$15),0)+IFERROR(-PPMT(D$22,((4-1)*12)+6,D$23,D$15),0)+IFERROR(-PPMT(D$22,((4-1)*12)+7,D$23,D$15),0)+IFERROR(-PPMT(D$22,((4-1)*12)+8,D$23,D$15),0)+IFERROR(-PPMT(D$22,((4-1)*12)+9,D$23,D$15),0)+IFERROR(-PPMT(D$22,((4-1)*12)+10,D$23,D$15),0)+IFERROR(-PPMT(D$22,((4-1)*12)+11,D$23,D$15),0)+IFERROR(-PPMT(D$22,((4-1)*12)+12,D$23,D$15),0),0) -> 30418.364 | I9: =IFERROR(IFERROR(-IPMT(D$22,((4-1)*12)+1,D$23,D$15),0)+IFERROR(-IPMT(D$22,((4-1)*12)+2,D$23,D$15),0)+IFERROR(-IPMT(D$22,((4-1)*12)+3,D$23,D$15),0)+IFERROR(-IPMT(D$22,((4-1)*12)+4,D$23,D$15),0)+IFERROR(-IPMT(D$22,((4-1)*12)+5,D$23,D$15),0)+IFERROR(-IPMT(D$22,((4-1)*12)+6,D$23,D$15),0)+IFERROR(-IPMT(D$22,((4-1)*12)+7,D$23,D$15),0)+IFERROR(-IPMT(D$22,((4-1)*12)+8,D$23,D$15),0)+IFERROR(-IPMT(D$22,((4-1)*12)+9,D$23,D$15),0)+IFERROR(-IPMT(D$22,((4-1)*12)+10,D$23,D$15),0)+IFERROR(-IPMT(D$22,((4-1)*12)+11,D$23,D$15),0)+IFERROR(-IPMT(D$22,((4-1)*12)+12,D$23,D$15),0),0) -> 49621.513
B10: 5 | C10: Total Acquisition Costs (AED) | D10: 90000 | E10: 60000 | G10: 5 | H10: =IFERROR(IFERROR(-PPMT(D$22,((5-1)*12)+1,D$23,D$15),0)+IFERROR(-PPMT(D$22,((5-1)*12)+2,D$23,D$15),0)+IFERROR(-PPMT(D$22,((5-1)*12)+3,D$23,D$15),0)+IFERROR(-PPMT(D$22,((5-1)*12)+4,D$23,D$15),0)+IFERROR(-PPMT(D$22,((5-1)*12)+5,D$23,D$15),0)+IFERROR(-PPMT(D$22,((5-1)*12)+6,D$23,D$15),0)+IFERROR(-PPMT(D$22,((5-1)*12)+7,D$23,D$15),0)+IFERROR(-PPMT(D$22,((5-1)*12)+8,D$23,D$15),0)+IFERROR(-PPMT(D$22,((5-1)*12)+9,D$23,D$15),0)+IFERROR(-PPMT(D$22,((5-1)*12)+10,D$23,D$15),0)+IFERROR(-PPMT(D$22,((5-1)*12)+11,D$23,D$15),0)+IFERROR(-PPMT(D$22,((5-1)*12)+12,D$23,D$15),0),0) -> 31815.778 | I10: =IFERROR(IFERROR(-IPMT(D$22,((5-1)*12)+1,D$23,D$15),0)+IFERROR(-IPMT(D$22,((5-1)*12)+2,D$23,D$15),0)+IFERROR(-IPMT(D$22,((5-1)*12)+3,D$23,D$15),0)+IFERROR(-IPMT(D$22,((5-1)*12)+4,D$23,D$15),0)+IFERROR(-IPMT(D$22,((5-1)*12)+5,D$23,D$15),0)+IFERROR(-IPMT(D$22,((5-1)*12)+6,D$23,D$15),0)+IFERROR(-IPMT(D$22,((5-1)*12)+7,D$23,D$15),0)+IFERROR(-IPMT(D$22,((5-1)*12)+8,D$23,D$15),0)+IFERROR(-IPMT(D$22,((5-1)*12)+9,D$23,D$15),0)+IFERROR(-IPMT(D$22,((5-1)*12)+10,D$23,D$15),0)+IFERROR(-IPMT(D$22,((5-1)*12)+11,D$23,D$15),0)+IFERROR(-IPMT(D$22,((5-1)*12)+12,D$23,D$15),0),0) -> 48224.099
G11: 6 | H11: =IFERROR(IFERROR(-PPMT(D$22,((6-1)*12)+1,D$23,D$15),0)+IFERROR(-PPMT(D$22,((6-1)*12)+2,D$23,D$15),0)+IFERROR(-PPMT(D$22,((6-1)*12)+3,D$23,D$15),0)+IFERROR(-PPMT(D$22,((6-1)*12)+4,D$23,D$15),0)+IFERROR(-PPMT(D$22,((6-1)*12)+5,D$23,D$15),0)+IFERROR(-PPMT(D$22,((6-1)*12)+6,D$23,D$15),0)+IFERROR(-PPMT(D$22,((6-1)*12)+7,D$23,D$15),0)+IFERROR(-PPMT(D$22,((6-1)*12)+8,D$23,D$15),0)+IFERROR(-PPMT(D$22,((6-1)*12)+9,D$23,D$15),0)+IFERROR(-PPMT(D$22,((6-1)*12)+10,D$23,D$15),0)+IFERROR(-PPMT(D$22,((6-1)*12)+11,D$23,D$15),0)+IFERROR(-PPMT(D$22,((6-1)*12)+12,D$23,D$15),0),0) -> 33277.389 | I11: =IFERROR(IFERROR(-IPMT(D$22,((6-1)*12)+1,D$23,D$15),0)+IFERROR(-IPMT(D$22,((6-1)*12)+2,D$23,D$15),0)+IFERROR(-IPMT(D$22,((6-1)*12)+3,D$23,D$15),0)+IFERROR(-IPMT(D$22,((6-1)*12)+4,D$23,D$15),0)+IFERROR(-IPMT(D$22,((6-1)*12)+5,D$23,D$15),0)+IFERROR(-IPMT(D$22,((6-1)*12)+6,D$23,D$15),0)+IFERROR(-IPMT(D$22,((6-1)*12)+7,D$23,D$15),0)+IFERROR(-IPMT(D$22,((6-1)*12)+8,D$23,D$15),0)+IFERROR(-IPMT(D$22,((6-1)*12)+9,D$23,D$15),0)+IFERROR(-IPMT(D$22,((6-1)*12)+10,D$23,D$15),0)+IFERROR(-IPMT(D$22,((6-1)*12)+11,D$23,D$15),0)+IFERROR(-IPMT(D$22,((6-1)*12)+12,D$23,D$15),0),0) -> 46762.488
C12: ② MORTGAGE PARAMETERS (UAE Bank Standards) | G12: 7 | H12: =IFERROR(IFERROR(-PPMT(D$22,((7-1)*12)+1,D$23,D$15),0)+IFERROR(-PPMT(D$22,((7-1)*12)+2,D$23,D$15),0)+IFERROR(-PPMT(D$22,((7-1)*12)+3,D$23,D$15),0)+IFERROR(-PPMT(D$22,((7-1)*12)+4,D$23,D$15),0)+IFERROR(-PPMT(D$22,((7-1)*12)+5,D$23,D$15),0)+IFERROR(-PPMT(D$22,((7-1)*12)+6,D$23,D$15),0)+IFERROR(-PPMT(D$22,((7-1)*12)+7,D$23,D$15),0)+IFERROR(-PPMT(D$22,((7-1)*12)+8,D$23,D$15),0)+IFERROR(-PPMT(D$22,((7-1)*12)+9,D$23,D$15),0)+IFERROR(-PPMT(D$22,((7-1)*12)+10,D$23,D$15),0)+IFERROR(-PPMT(D$22,((7-1)*12)+11,D$23,D$15),0)+IFERROR(-PPMT(D$22,((7-1)*12)+12,D$23,D$15),0),0) -> 34806.147 | I12: =IFERROR(IFERROR(-IPMT(D$22,((7-1)*12)+1,D$23,D$15),0)+IFERROR(-IPMT(D$22,((7-1)*12)+2,D$23,D$15),0)+IFERROR(-IPMT(D$22,((7-1)*12)+3,D$23,D$15),0)+IFERROR(-IPMT(D$22,((7-1)*12)+4,D$23,D$15),0)+IFERROR(-IPMT(D$22,((7-1)*12)+5,D$23,D$15),0)+IFERROR(-IPMT(D$22,((7-1)*12)+6,D$23,D$15),0)+IFERROR(-IPMT(D$22,((7-1)*12)+7,D$23,D$15),0)+IFERROR(-IPMT(D$22,((7-1)*12)+8,D$23,D$15),0)+IFERROR(-IPMT(D$22,((7-1)*12)+9,D$23,D$15),0)+IFERROR(-IPMT(D$22,((7-1)*12)+10,D$23,D$15),0)+IFERROR(-IPMT(D$22,((7-1)*12)+11,D$23,D$15),0)+IFERROR(-IPMT(D$22,((7-1)*12)+12,D$23,D$15),0),0) -> 45233.73
B13: 6 | C13: Down Payment (%) | D13: 0.2 | E13: N/A — full cash | G13: 8 | H13: =IFERROR(IFERROR(-PPMT(D$22,((8-1)*12)+1,D$23,D$15),0)+IFERROR(-PPMT(D$22,((8-1)*12)+2,D$23,D$15),0)+IFERROR(-PPMT(D$22,((8-1)*12)+3,D$23,D$15),0)+IFERROR(-PPMT(D$22,((8-1)*12)+4,D$23,D$15),0)+IFERROR(-PPMT(D$22,((8-1)*12)+5,D$23,D$15),0)+IFERROR(-PPMT(D$22,((8-1)*12)+6,D$23,D$15),0)+IFERROR(-PPMT(D$22,((8-1)*12)+7,D$23,D$15),0)+IFERROR(-PPMT(D$22,((8-1)*12)+8,D$23,D$15),0)+IFERROR(-PPMT(D$22,((8-1)*12)+9,D$23,D$15),0)+IFERROR(-PPMT(D$22,((8-1)*12)+10,D$23,D$15),0)+IFERROR(-PPMT(D$22,((8-1)*12)+11,D$23,D$15),0)+IFERROR(-PPMT(D$22,((8-1)*12)+12,D$23,D$15),0),0) -> 36405.135 | I13: =IFERROR(IFERROR(-IPMT(D$22,((8-1)*12)+1,D$23,D$15),0)+IFERROR(-IPMT(D$22,((8-1)*12)+2,D$23,D$15),0)+IFERROR(-IPMT(D$22,((8-1)*12)+3,D$23,D$15),0)+IFERROR(-IPMT(D$22,((8-1)*12)+4,D$23,D$15),0)+IFERROR(-IPMT(D$22,((8-1)*12)+5,D$23,D$15),0)+IFERROR(-IPMT(D$22,((8-1)*12)+6,D$23,D$15),0)+IFERROR(-IPMT(D$22,((8-1)*12)+7,D$23,D$15),0)+IFERROR(-IPMT(D$22,((8-1)*12)+8,D$23,D$15),0)+IFERROR(-IPMT(D$22,((8-1)*12)+9,D$23,D$15),0)+IFERROR(-IPMT(D$22,((8-1)*12)+10,D$23,D$15),0)+IFERROR(-IPMT(D$22,((8-1)*12)+11,D$23,D$15),0)+IFERROR(-IPMT(D$22,((8-1)*12)+12,D$23,D$15),0),0) -> 43634.742
B14: 7 | C14: ↳ Down Payment Amount (AED) | D14: =D7*D13 -> 300000 | E14: =E7 -> 1500000 | G14: 9 | H14: =IFERROR(IFERROR(-PPMT(D$22,((9-1)*12)+1,D$23,D$15),0)+IFERROR(-PPMT(D$22,((9-1)*12)+2,D$23,D$15),0)+IFERROR(-PPMT(D$22,((9-1)*12)+3,D$23,D$15),0)+IFERROR(-PPMT(D$22,((9-1)*12)+4,D$23,D$15),0)+IFERROR(-PPMT(D$22,((9-1)*12)+5,D$23,D$15),0)+IFERROR(-PPMT(D$22,((9-1)*12)+6,D$23,D$15),0)+IFERROR(-PPMT(D$22,((9-1)*12)+7,D$23,D$15),0)+IFERROR(-PPMT(D$22,((9-1)*12)+8,D$23,D$15),0)+IFERROR(-PPMT(D$22,((9-1)*12)+9,D$23,D$15),0)+IFERROR(-PPMT(D$22,((9-1)*12)+10,D$23,D$15),0)+IFERROR(-PPMT(D$22,((9-1)*12)+11,D$23,D$15),0)+IFERROR(-PPMT(D$22,((9-1)*12)+12,D$23,D$15),0),0) -> 38077.58 | I14: =IFERROR(IFERROR(-IPMT(D$22,((9-1)*12)+1,D$23,D$15),0)+IFERROR(-IPMT(D$22,((9-1)*12)+2,D$23,D$15),0)+IFERROR(-IPMT(D$22,((9-1)*12)+3,D$23,D$15),0)+IFERROR(-IPMT(D$22,((9-1)*12)+4,D$23,D$15),0)+IFERROR(-IPMT(D$22,((9-1)*12)+5,D$23,D$15),0)+IFERROR(-IPMT(D$22,((9-1)*12)+6,D$23,D$15),0)+IFERROR(-IPMT(D$22,((9-1)*12)+7,D$23,D$15),0)+IFERROR(-IPMT(D$22,((9-1)*12)+8,D$23,D$15),0)+IFERROR(-IPMT(D$22,((9-1)*12)+9,D$23,D$15),0)+IFERROR(-IPMT(D$22,((9-1)*12)+10,D$23,D$15),0)+IFERROR(-IPMT(D$22,((9-1)*12)+11,D$23,D$15),0)+IFERROR(-IPMT(D$22,((9-1)*12)+12,D$23,D$15),0),0) -> 41962.296
B15: 8 | C15: ↳ Loan Amount (AED) | D15: =D7-D14 -> 1200000 | E15: =0 -> 0 | G15: 10 | H15: =IFERROR(IFERROR(-PPMT(D$22,((10-1)*12)+1,D$23,D$15),0)+IFERROR(-PPMT(D$22,((10-1)*12)+2,D$23,D$15),0)+IFERROR(-PPMT(D$22,((10-1)*12)+3,D$23,D$15),0)+IFERROR(-PPMT(D$22,((10-1)*12)+4,D$23,D$15),0)+IFERROR(-PPMT(D$22,((10-1)*12)+5,D$23,D$15),0)+IFERROR(-PPMT(D$22,((10-1)*12)+6,D$23,D$15),0)+IFERROR(-PPMT(D$22,((10-1)*12)+7,D$23,D$15),0)+IFERROR(-PPMT(D$22,((10-1)*12)+8,D$23,D$15),0)+IFERROR(-PPMT(D$22,((10-1)*12)+9,D$23,D$15),0)+IFERROR(-PPMT(D$22,((10-1)*12)+10,D$23,D$15),0)+IFERROR(-PPMT(D$22,((10-1)*12)+11,D$23,D$15),0)+IFERROR(-PPMT(D$22,((10-1)*12)+12,D$23,D$15),0),0) -> 39826.858 | I15: =IFERROR(IFERROR(-IPMT(D$22,((10-1)*12)+1,D$23,D$15),0)+IFERROR(-IPMT(D$22,((10-1)*12)+2,D$23,D$15),0)+IFERROR(-IPMT(D$22,((10-1)*12)+3,D$23,D$15),0)+IFERROR(-IPMT(D$22,((10-1)*12)+4,D$23,D$15),0)+IFERROR(-IPMT(D$22,((10-1)*12)+5,D$23,D$15),0)+IFERROR(-IPMT(D$22,((10-1)*12)+6,D$23,D$15),0)+IFERROR(-IPMT(D$22,((10-1)*12)+7,D$23,D$15),0)+IFERROR(-IPMT(D$22,((10-1)*12)+8,D$23,D$15),0)+IFERROR(-IPMT(D$22,((10-1)*12)+9,D$23,D$15),0)+IFERROR(-IPMT(D$22,((10-1)*12)+10,D$23,D$15),0)+IFERROR(-IPMT(D$22,((10-1)*12)+11,D$23,D$15),0)+IFERROR(-IPMT(D$22,((10-1)*12)+12,D$23,D$15),0),0) -> 40213.019
B16: 9 | C16: Annual Interest Rate (%) | D16: 0.045 | E16: N/A | G16: 11 | H16: =IFERROR(IFERROR(-PPMT(D$22,((11-1)*12)+1,D$23,D$15),0)+IFERROR(-PPMT(D$22,((11-1)*12)+2,D$23,D$15),0)+IFERROR(-PPMT(D$22,((11-1)*12)+3,D$23,D$15),0)+IFERROR(-PPMT(D$22,((11-1)*12)+4,D$23,D$15),0)+IFERROR(-PPMT(D$22,((11-1)*12)+5,D$23,D$15),0)+IFERROR(-PPMT(D$22,((11-1)*12)+6,D$23,D$15),0)+IFERROR(-PPMT(D$22,((11-1)*12)+7,D$23,D$15),0)+IFERROR(-PPMT(D$22,((11-1)*12)+8,D$23,D$15),0)+IFERROR(-PPMT(D$22,((11-1)*12)+9,D$23,D$15),0)+IFERROR(-PPMT(D$22,((11-1)*12)+10,D$23,D$15),0)+IFERROR(-PPMT(D$22,((11-1)*12)+11,D$23,D$15),0)+IFERROR(-PPMT(D$22,((11-1)*12)+12,D$23,D$15),0),0) -> 41656.497 | I16: =IFERROR(IFERROR(-IPMT(D$22,((11-1)*12)+1,D$23,D$15),0)+IFERROR(-IPMT(D$22,((11-1)*12)+2,D$23,D$15),0)+IFERROR(-IPMT(D$22,((11-1)*12)+3,D$23,D$15),0)+IFERROR(-IPMT(D$22,((11-1)*12)+4,D$23,D$15),0)+IFERROR(-IPMT(D$22,((11-1)*12)+5,D$23,D$15),0)+IFERROR(-IPMT(D$22,((11-1)*12)+6,D$23,D$15),0)+IFERROR(-IPMT(D$22,((11-1)*12)+7,D$23,D$15),0)+IFERROR(-IPMT(D$22,((11-1)*12)+8,D$23,D$15),0)+IFERROR(-IPMT(D$22,((11-1)*12)+9,D$23,D$15),0)+IFERROR(-IPMT(D$22,((11-1)*12)+10,D$23,D$15),0)+IFERROR(-IPMT(D$22,((11-1)*12)+11,D$23,D$15),0)+IFERROR(-IPMT(D$22,((11-1)*12)+12,D$23,D$15),0),0) -> 38383.38
B17: 10 | C17: Loan Term (years) | D17: 25 | E17: N/A | G17: 12 | H17: =IFERROR(IFERROR(-PPMT(D$22,((12-1)*12)+1,D$23,D$15),0)+IFERROR(-PPMT(D$22,((12-1)*12)+2,D$23,D$15),0)+IFERROR(-PPMT(D$22,((12-1)*12)+3,D$23,D$15),0)+IFERROR(-PPMT(D$22,((12-1)*12)+4,D$23,D$15),0)+IFERROR(-PPMT(D$22,((12-1)*12)+5,D$23,D$15),0)+IFERROR(-PPMT(D$22,((12-1)*12)+6,D$23,D$15),0)+IFERROR(-PPMT(D$22,((12-1)*12)+7,D$23,D$15),0)+IFERROR(-PPMT(D$22,((12-1)*12)+8,D$23,D$15),0)+IFERROR(-PPMT(D$22,((12-1)*12)+9,D$23,D$15),0)+IFERROR(-PPMT(D$22,((12-1)*12)+10,D$23,D$15),0)+IFERROR(-PPMT(D$22,((12-1)*12)+11,D$23,D$15),0)+IFERROR(-PPMT(D$22,((12-1)*12)+12,D$23,D$15),0),0) -> 43570.189 | I17: =IFERROR(IFERROR(-IPMT(D$22,((12-1)*12)+1,D$23,D$15),0)+IFERROR(-IPMT(D$22,((12-1)*12)+2,D$23,D$15),0)+IFERROR(-IPMT(D$22,((12-1)*12)+3,D$23,D$15),0)+IFERROR(-IPMT(D$22,((12-1)*12)+4,D$23,D$15),0)+IFERROR(-IPMT(D$22,((12-1)*12)+5,D$23,D$15),0)+IFERROR(-IPMT(D$22,((12-1)*12)+6,D$23,D$15),0)+IFERROR(-IPMT(D$22,((12-1)*12)+7,D$23,D$15),0)+IFERROR(-IPMT(D$22,((12-1)*12)+8,D$23,D$15),0)+IFERROR(-IPMT(D$22,((12-1)*12)+9,D$23,D$15),0)+IFERROR(-IPMT(D$22,((12-1)*12)+10,D$23,D$15),0)+IFERROR(-IPMT(D$22,((12-1)*12)+11,D$23,D$15),0)+IFERROR(-IPMT(D$22,((12-1)*12)+12,D$23,D$15),0),0) -> 36469.688
B18: 11 | C18: Mortgage Registration Fee (AED) | D18: =D15*0.0025+290 -> 3290 | E18: =0 -> 0 | G18: 13 | H18: =IFERROR(IFERROR(-PPMT(D$22,((13-1)*12)+1,D$23,D$15),0)+IFERROR(-PPMT(D$22,((13-1)*12)+2,D$23,D$15),0)+IFERROR(-PPMT(D$22,((13-1)*12)+3,D$23,D$15),0)+IFERROR(-PPMT(D$22,((13-1)*12)+4,D$23,D$15),0)+IFERROR(-PPMT(D$22,((13-1)*12)+5,D$23,D$15),0)+IFERROR(-PPMT(D$22,((13-1)*12)+6,D$23,D$15),0)+IFERROR(-PPMT(D$22,((13-1)*12)+7,D$23,D$15),0)+IFERROR(-PPMT(D$22,((13-1)*12)+8,D$23,D$15),0)+IFERROR(-PPMT(D$22,((13-1)*12)+9,D$23,D$15),0)+IFERROR(-PPMT(D$22,((13-1)*12)+10,D$23,D$15),0)+IFERROR(-PPMT(D$22,((13-1)*12)+11,D$23,D$15),0)+IFERROR(-PPMT(D$22,((13-1)*12)+12,D$23,D$15),0),0) -> 45571.796 | I18: =IFERROR(IFERROR(-IPMT(D$22,((13-1)*12)+1,D$23,D$15),0)+IFERROR(-IPMT(D$22,((13-1)*12)+2,D$23,D$15),0)+IFERROR(-IPMT(D$22,((13-1)*12)+3,D$23,D$15),0)+IFERROR(-IPMT(D$22,((13-1)*12)+4,D$23,D$15),0)+IFERROR(-IPMT(D$22,((13-1)*12)+5,D$23,D$15),0)+IFERROR(-IPMT(D$22,((13-1)*12)+6,D$23,D$15),0)+IFERROR(-IPMT(D$22,((13-1)*12)+7,D$23,D$15),0)+IFERROR(-IPMT(D$22,((13-1)*12)+8,D$23,D$15),0)+IFERROR(-IPMT(D$22,((13-1)*12)+9,D$23,D$15),0)+IFERROR(-IPMT(D$22,((13-1)*12)+10,D$23,D$15),0)+IFERROR(-IPMT(D$22,((13-1)*12)+11,D$23,D$15),0)+IFERROR(-IPMT(D$22,((13-1)*12)+12,D$23,D$15),0),0) -> 34468.081
B19: 12 | C19: Property Valuation Fee (AED) | D19: 3000 | E19: =0 -> 0 | G19: 14 | H19: =IFERROR(IFERROR(-PPMT(D$22,((14-1)*12)+1,D$23,D$15),0)+IFERROR(-PPMT(D$22,((14-1)*12)+2,D$23,D$15),0)+IFERROR(-PPMT(D$22,((14-1)*12)+3,D$23,D$15),0)+IFERROR(-PPMT(D$22,((14-1)*12)+4,D$23,D$15),0)+IFERROR(-PPMT(D$22,((14-1)*12)+5,D$23,D$15),0)+IFERROR(-PPMT(D$22,((14-1)*12)+6,D$23,D$15),0)+IFERROR(-PPMT(D$22,((14-1)*12)+7,D$23,D$15),0)+IFERROR(-PPMT(D$22,((14-1)*12)+8,D$23,D$15),0)+IFERROR(-PPMT(D$22,((14-1)*12)+9,D$23,D$15),0)+IFERROR(-PPMT(D$22,((14-1)*12)+10,D$23,D$15),0)+IFERROR(-PPMT(D$22,((14-1)*12)+11,D$23,D$15),0)+IFERROR(-PPMT(D$22,((14-1)*12)+12,D$23,D$15),0),0) -> 47665.356 | I19: =IFERROR(IFERROR(-IPMT(D$22,((14-1)*12)+1,D$23,D$15),0)+IFERROR(-IPMT(D$22,((14-1)*12)+2,D$23,D$15),0)+IFERROR(-IPMT(D$22,((14-1)*12)+3,D$23,D$15),0)+IFERROR(-IPMT(D$22,((14-1)*12)+4,D$23,D$15),0)+IFERROR(-IPMT(D$22,((14-1)*12)+5,D$23,D$15),0)+IFERROR(-IPMT(D$22,((14-1)*12)+6,D$23,D$15),0)+IFERROR(-IPMT(D$22,((14-1)*12)+7,D$23,D$15),0)+IFERROR(-IPMT(D$22,((14-1)*12)+8,D$23,D$15),0)+IFERROR(-IPMT(D$22,((14-1)*12)+9,D$23,D$15),0)+IFERROR(-IPMT(D$22,((14-1)*12)+10,D$23,D$15),0)+IFERROR(-IPMT(D$22,((14-1)*12)+11,D$23,D$15),0)+IFERROR(-IPMT(D$22,((14-1)*12)+12,D$23,D$15),0),0) -> 32374.521
G20: 15 | H20: =IFERROR(IFERROR(-PPMT(D$22,((15-1)*12)+1,D$23,D$15),0)+IFERROR(-PPMT(D$22,((15-1)*12)+2,D$23,D$15),0)+IFERROR(-PPMT(D$22,((15-1)*12)+3,D$23,D$15),0)+IFERROR(-PPMT(D$22,((15-1)*12)+4,D$23,D$15),0)+IFERROR(-PPMT(D$22,((15-1)*12)+5,D$23,D$15),0)+IFERROR(-PPMT(D$22,((15-1)*12)+6,D$23,D$15),0)+IFERROR(-PPMT(D$22,((15-1)*12)+7,D$23,D$15),0)+IFERROR(-PPMT(D$22,((15-1)*12)+8,D$23,D$15),0)+IFERROR(-PPMT(D$22,((15-1)*12)+9,D$23,D$15),0)+IFERROR(-PPMT(D$22,((15-1)*12)+10,D$23,D$15),0)+IFERROR(-PPMT(D$22,((15-1)*12)+11,D$23,D$15),0)+IFERROR(-PPMT(D$22,((15-1)*12)+12,D$23,D$15),0),0) -> 49855.094 | I20: =IFERROR(IFERROR(-IPMT(D$22,((15-1)*12)+1,D$23,D$15),0)+IFERROR(-IPMT(D$22,((15-1)*12)+2,D$23,D$15),0)+IFERROR(-IPMT(D$22,((15-1)*12)+3,D$23,D$15),0)+IFERROR(-IPMT(D$22,((15-1)*12)+4,D$23,D$15),0)+IFERROR(-IPMT(D$22,((15-1)*12)+5,D$23,D$15),0)+IFERROR(-IPMT(D$22,((15-1)*12)+6,D$23,D$15),0)+IFERROR(-IPMT(D$22,((15-1)*12)+7,D$23,D$15),0)+IFERROR(-IPMT(D$22,((15-1)*12)+8,D$23,D$15),0)+IFERROR(-IPMT(D$22,((15-1)*12)+9,D$23,D$15),0)+IFERROR(-IPMT(D$22,((15-1)*12)+10,D$23,D$15),0)+IFERROR(-IPMT(D$22,((15-1)*12)+11,D$23,D$15),0)+IFERROR(-IPMT(D$22,((15-1)*12)+12,D$23,D$15),0),0) -> 30184.783
C21: ③ MORTGAGE CALCULATIONS | G21: 16 | H21: =IFERROR(IFERROR(-PPMT(D$22,((16-1)*12)+1,D$23,D$15),0)+IFERROR(-PPMT(D$22,((16-1)*12)+2,D$23,D$15),0)+IFERROR(-PPMT(D$22,((16-1)*12)+3,D$23,D$15),0)+IFERROR(-PPMT(D$22,((16-1)*12)+4,D$23,D$15),0)+IFERROR(-PPMT(D$22,((16-1)*12)+5,D$23,D$15),0)+IFERROR(-PPMT(D$22,((16-1)*12)+6,D$23,D$15),0)+IFERROR(-PPMT(D$22,((16-1)*12)+7,D$23,D$15),0)+IFERROR(-PPMT(D$22,((16-1)*12)+8,D$23,D$15),0)+IFERROR(-PPMT(D$22,((16-1)*12)+9,D$23,D$15),0)+IFERROR(-PPMT(D$22,((16-1)*12)+10,D$23,D$15),0)+IFERROR(-PPMT(D$22,((16-1)*12)+11,D$23,D$15),0)+IFERROR(-PPMT(D$22,((16-1)*12)+12,D$23,D$15),0),0) -> 52145.428 | I21: =IFERROR(IFERROR(-IPMT(D$22,((16-1)*12)+1,D$23,D$15),0)+IFERROR(-IPMT(D$22,((16-1)*12)+2,D$23,D$15),0)+IFERROR(-IPMT(D$22,((16-1)*12)+3,D$23,D$15),0)+IFERROR(-IPMT(D$22,((16-1)*12)+4,D$23,D$15),0)+IFERROR(-IPMT(D$22,((16-1)*12)+5,D$23,D$15),0)+IFERROR(-IPMT(D$22,((16-1)*12)+6,D$23,D$15),0)+IFERROR(-IPMT(D$22,((16-1)*12)+7,D$23,D$15),0)+IFERROR(-IPMT(D$22,((16-1)*12)+8,D$23,D$15),0)+IFERROR(-IPMT(D$22,((16-1)*12)+9,D$23,D$15),0)+IFERROR(-IPMT(D$22,((16-1)*12)+10,D$23,D$15),0)+IFERROR(-IPMT(D$22,((16-1)*12)+11,D$23,D$15),0)+IFERROR(-IPMT(D$22,((16-1)*12)+12,D$23,D$15),0),0) -> 27894.448
C22: Monthly Interest Rate | D22: =IFERROR(D16/12,0) -> 0.00375 | E22: =0 -> 0 | G22: 17 | H22: =IFERROR(IFERROR(-PPMT(D$22,((17-1)*12)+1,D$23,D$15),0)+IFERROR(-PPMT(D$22,((17-1)*12)+2,D$23,D$15),0)+IFERROR(-PPMT(D$22,((17-1)*12)+3,D$23,D$15),0)+IFERROR(-PPMT(D$22,((17-1)*12)+4,D$23,D$15),0)+IFERROR(-PPMT(D$22,((17-1)*12)+5,D$23,D$15),0)+IFERROR(-PPMT(D$22,((17-1)*12)+6,D$23,D$15),0)+IFERROR(-PPMT(D$22,((17-1)*12)+7,D$23,D$15),0)+IFERROR(-PPMT(D$22,((17-1)*12)+8,D$23,D$15),0)+IFERROR(-PPMT(D$22,((17-1)*12)+9,D$23,D$15),0)+IFERROR(-PPMT(D$22,((17-1)*12)+10,D$23,D$15),0)+IFERROR(-PPMT(D$22,((17-1)*12)+11,D$23,D$15),0)+IFERROR(-PPMT(D$22,((17-1)*12)+12,D$23,D$15),0),0) -> 54540.98 | I22: =IFERROR(IFERROR(-IPMT(D$22,((17-1)*12)+1,D$23,D$15),0)+IFERROR(-IPMT(D$22,((17-1)*12)+2,D$23,D$15),0)+IFERROR(-IPMT(D$22,((17-1)*12)+3,D$23,D$15),0)+IFERROR(-IPMT(D$22,((17-1)*12)+4,D$23,D$15),0)+IFERROR(-IPMT(D$22,((17-1)*12)+5,D$23,D$15),0)+IFERROR(-IPMT(D$22,((17-1)*12)+6,D$23,D$15),0)+IFERROR(-IPMT(D$22,((17-1)*12)+7,D$23,D$15),0)+IFERROR(-IPMT(D$22,((17-1)*12)+8,D$23,D$15),0)+IFERROR(-IPMT(D$22,((17-1)*12)+9,D$23,D$15),0)+IFERROR(-IPMT(D$22,((17-1)*12)+10,D$23,D$15),0)+IFERROR(-IPMT(D$22,((17-1)*12)+11,D$23,D$15),0)+IFERROR(-IPMT(D$22,((17-1)*12)+12,D$23,D$15),0),0) -> 25498.896
C23: Total Payments (months) | D23: =D17*12 -> 300 | E23: =0 -> 0 | G23: 18 | H23: =IFERROR(IFERROR(-PPMT(D$22,((18-1)*12)+1,D$23,D$15),0)+IFERROR(-PPMT(D$22,((18-1)*12)+2,D$23,D$15),0)+IFERROR(-PPMT(D$22,((18-1)*12)+3,D$23,D$15),0)+IFERROR(-PPMT(D$22,((18-1)*12)+4,D$23,D$15),0)+IFERROR(-PPMT(D$22,((18-1)*12)+5,D$23,D$15),0)+IFERROR(-PPMT(D$22,((18-1)*12)+6,D$23,D$15),0)+IFERROR(-PPMT(D$22,((18-1)*12)+7,D$23,D$15),0)+IFERROR(-PPMT(D$22,((18-1)*12)+8,D$23,D$15),0)+IFERROR(-PPMT(D$22,((18-1)*12)+9,D$23,D$15),0)+IFERROR(-PPMT(D$22,((18-1)*12)+10,D$23,D$15),0)+IFERROR(-PPMT(D$22,((18-1)*12)+11,D$23,D$15),0)+IFERROR(-PPMT(D$22,((18-1)*12)+12,D$23,D$15),0),0) -> 57046.583 | I23: =IFERROR(IFERROR(-IPMT(D$22,((18-1)*12)+1,D$23,D$15),0)+IFERROR(-IPMT(D$22,((18-1)*12)+2,D$23,D$15),0)+IFERROR(-IPMT(D$22,((18-1)*12)+3,D$23,D$15),0)+IFERROR(-IPMT(D$22,((18-1)*12)+4,D$23,D$15),0)+IFERROR(-IPMT(D$22,((18-1)*12)+5,D$23,D$15),0)+IFERROR(-IPMT(D$22,((18-1)*12)+6,D$23,D$15),0)+IFERROR(-IPMT(D$22,((18-1)*12)+7,D$23,D$15),0)+IFERROR(-IPMT(D$22,((18-1)*12)+8,D$23,D$15),0)+IFERROR(-IPMT(D$22,((18-1)*12)+9,D$23,D$15),0)+IFERROR(-IPMT(D$22,((18-1)*12)+10,D$23,D$15),0)+IFERROR(-IPMT(D$22,((18-1)*12)+11,D$23,D$15),0)+IFERROR(-IPMT(D$22,((18-1)*12)+12,D$23,D$15),0),0) -> 22993.293
B24: M1 | C24: Monthly Mortgage Payment (AED) | D24: =IFERROR(-PMT(D22,D23,D15),0) -> 6669.9897 | E24: =0 -> 0 | G24: 19 | H24: =IFERROR(IFERROR(-PPMT(D$22,((19-1)*12)+1,D$23,D$15),0)+IFERROR(-PPMT(D$22,((19-1)*12)+2,D$23,D$15),0)+IFERROR(-PPMT(D$22,((19-1)*12)+3,D$23,D$15),0)+IFERROR(-PPMT(D$22,((19-1)*12)+4,D$23,D$15),0)+IFERROR(-PPMT(D$22,((19-1)*12)+5,D$23,D$15),0)+IFERROR(-PPMT(D$22,((19-1)*12)+6,D$23,D$15),0)+IFERROR(-PPMT(D$22,((19-1)*12)+7,D$23,D$15),0)+IFERROR(-PPMT(D$22,((19-1)*12)+8,D$23,D$15),0)+IFERROR(-PPMT(D$22,((19-1)*12)+9,D$23,D$15),0)+IFERROR(-PPMT(D$22,((19-1)*12)+10,D$23,D$15),0)+IFERROR(-PPMT(D$22,((19-1)*12)+11,D$23,D$15),0)+IFERROR(-PPMT(D$22,((19-1)*12)+12,D$23,D$15),0),0) -> 59667.293 | I24: =IFERROR(IFERROR(-IPMT(D$22,((19-1)*12)+1,D$23,D$15),0)+IFERROR(-IPMT(D$22,((19-1)*12)+2,D$23,D$15),0)+IFERROR(-IPMT(D$22,((19-1)*12)+3,D$23,D$15),0)+IFERROR(-IPMT(D$22,((19-1)*12)+4,D$23,D$15),0)+IFERROR(-IPMT(D$22,((19-1)*12)+5,D$23,D$15),0)+IFERROR(-IPMT(D$22,((19-1)*12)+6,D$23,D$15),0)+IFERROR(-IPMT(D$22,((19-1)*12)+7,D$23,D$15),0)+IFERROR(-IPMT(D$22,((19-1)*12)+8,D$23,D$15),0)+IFERROR(-IPMT(D$22,((19-1)*12)+9,D$23,D$15),0)+IFERROR(-IPMT(D$22,((19-1)*12)+10,D$23,D$15),0)+IFERROR(-IPMT(D$22,((19-1)*12)+11,D$23,D$15),0)+IFERROR(-IPMT(D$22,((19-1)*12)+12,D$23,D$15),0),0) -> 20372.583
B25: M2 | C25: Annual Mortgage Payment (AED) | D25: =D24*12 -> 80039.877 | E25: =0 -> 0 | G25: 20 | H25: =IFERROR(IFERROR(-PPMT(D$22,((20-1)*12)+1,D$23,D$15),0)+IFERROR(-PPMT(D$22,((20-1)*12)+2,D$23,D$15),0)+IFERROR(-PPMT(D$22,((20-1)*12)+3,D$23,D$15),0)+IFERROR(-PPMT(D$22,((20-1)*12)+4,D$23,D$15),0)+IFERROR(-PPMT(D$22,((20-1)*12)+5,D$23,D$15),0)+IFERROR(-PPMT(D$22,((20-1)*12)+6,D$23,D$15),0)+IFERROR(-PPMT(D$22,((20-1)*12)+7,D$23,D$15),0)+IFERROR(-PPMT(D$22,((20-1)*12)+8,D$23,D$15),0)+IFERROR(-PPMT(D$22,((20-1)*12)+9,D$23,D$15),0)+IFERROR(-PPMT(D$22,((20-1)*12)+10,D$23,D$15),0)+IFERROR(-PPMT(D$22,((20-1)*12)+11,D$23,D$15),0)+IFERROR(-PPMT(D$22,((20-1)*12)+12,D$23,D$15),0),0) -> 62408.399 | I25: =IFERROR(IFERROR(-IPMT(D$22,((20-1)*12)+1,D$23,D$15),0)+IFERROR(-IPMT(D$22,((20-1)*12)+2,D$23,D$15),0)+IFERROR(-IPMT(D$22,((20-1)*12)+3,D$23,D$15),0)+IFERROR(-IPMT(D$22,((20-1)*12)+4,D$23,D$15),0)+IFERROR(-IPMT(D$22,((20-1)*12)+5,D$23,D$15),0)+IFERROR(-IPMT(D$22,((20-1)*12)+6,D$23,D$15),0)+IFERROR(-IPMT(D$22,((20-1)*12)+7,D$23,D$15),0)+IFERROR(-IPMT(D$22,((20-1)*12)+8,D$23,D$15),0)+IFERROR(-IPMT(D$22,((20-1)*12)+9,D$23,D$15),0)+IFERROR(-IPMT(D$22,((20-1)*12)+10,D$23,D$15),0)+IFERROR(-IPMT(D$22,((20-1)*12)+11,D$23,D$15),0)+IFERROR(-IPMT(D$22,((20-1)*12)+12,D$23,D$15),0),0) -> 17631.478
C26: Total Interest Paid (full term) | D26: =IFERROR((D24*D23)-D15,0) -> 800996.92 | E26: =0 -> 0 | G26: 21 | H26: =IFERROR(IFERROR(-PPMT(D$22,((21-1)*12)+1,D$23,D$15),0)+IFERROR(-PPMT(D$22,((21-1)*12)+2,D$23,D$15),0)+IFERROR(-PPMT(D$22,((21-1)*12)+3,D$23,D$15),0)+IFERROR(-PPMT(D$22,((21-1)*12)+4,D$23,D$15),0)+IFERROR(-PPMT(D$22,((21-1)*12)+5,D$23,D$15),0)+IFERROR(-PPMT(D$22,((21-1)*12)+6,D$23,D$15),0)+IFERROR(-PPMT(D$22,((21-1)*12)+7,D$23,D$15),0)+IFERROR(-PPMT(D$22,((21-1)*12)+8,D$23,D$15),0)+IFERROR(-PPMT(D$22,((21-1)*12)+9,D$23,D$15),0)+IFERROR(-PPMT(D$22,((21-1)*12)+10,D$23,D$15),0)+IFERROR(-PPMT(D$22,((21-1)*12)+11,D$23,D$15),0)+IFERROR(-PPMT(D$22,((21-1)*12)+12,D$23,D$15),0),0) -> 65275.429 | I26: =IFERROR(IFERROR(-IPMT(D$22,((21-1)*12)+1,D$23,D$15),0)+IFERROR(-IPMT(D$22,((21-1)*12)+2,D$23,D$15),0)+IFERROR(-IPMT(D$22,((21-1)*12)+3,D$23,D$15),0)+IFERROR(-IPMT(D$22,((21-1)*12)+4,D$23,D$15),0)+IFERROR(-IPMT(D$22,((21-1)*12)+5,D$23,D$15),0)+IFERROR(-IPMT(D$22,((21-1)*12)+6,D$23,D$15),0)+IFERROR(-IPMT(D$22,((21-1)*12)+7,D$23,D$15),0)+IFERROR(-IPMT(D$22,((21-1)*12)+8,D$23,D$15),0)+IFERROR(-IPMT(D$22,((21-1)*12)+9,D$23,D$15),0)+IFERROR(-IPMT(D$22,((21-1)*12)+10,D$23,D$15),0)+IFERROR(-IPMT(D$22,((21-1)*12)+11,D$23,D$15),0)+IFERROR(-IPMT(D$22,((21-1)*12)+12,D$23,D$15),0),0) -> 14764.447
C27: Total Amount Repaid (principal+interest) | D27: =IFERROR(D24*D23,0) -> 2000996.9 | E27: =E7 -> 1500000 | G27: 22 | H27: =IFERROR(IFERROR(-PPMT(D$22,((22-1)*12)+1,D$23,D$15),0)+IFERROR(-PPMT(D$22,((22-1)*12)+2,D$23,D$15),0)+IFERROR(-PPMT(D$22,((22-1)*12)+3,D$23,D$15),0)+IFERROR(-PPMT(D$22,((22-1)*12)+4,D$23,D$15),0)+IFERROR(-PPMT(D$22,((22-1)*12)+5,D$23,D$15),0)+IFERROR(-PPMT(D$22,((22-1)*12)+6,D$23,D$15),0)+IFERROR(-PPMT(D$22,((22-1)*12)+7,D$23,D$15),0)+IFERROR(-PPMT(D$22,((22-1)*12)+8,D$23,D$15),0)+IFERROR(-PPMT(D$22,((22-1)*12)+9,D$23,D$15),0)+IFERROR(-PPMT(D$22,((22-1)*12)+10,D$23,D$15),0)+IFERROR(-PPMT(D$22,((22-1)*12)+11,D$23,D$15),0)+IFERROR(-PPMT(D$22,((22-1)*12)+12,D$23,D$15),0),0) -> 68274.171 | I27: =IFERROR(IFERROR(-IPMT(D$22,((22-1)*12)+1,D$23,D$15),0)+IFERROR(-IPMT(D$22,((22-1)*12)+2,D$23,D$15),0)+IFERROR(-IPMT(D$22,((22-1)*12)+3,D$23,D$15),0)+IFERROR(-IPMT(D$22,((22-1)*12)+4,D$23,D$15),0)+IFERROR(-IPMT(D$22,((22-1)*12)+5,D$23,D$15),0)+IFERROR(-IPMT(D$22,((22-1)*12)+6,D$23,D$15),0)+IFERROR(-IPMT(D$22,((22-1)*12)+7,D$23,D$15),0)+IFERROR(-IPMT(D$22,((22-1)*12)+8,D$23,D$15),0)+IFERROR(-IPMT(D$22,((22-1)*12)+9,D$23,D$15),0)+IFERROR(-IPMT(D$22,((22-1)*12)+10,D$23,D$15),0)+IFERROR(-IPMT(D$22,((22-1)*12)+11,D$23,D$15),0)+IFERROR(-IPMT(D$22,((22-1)*12)+12,D$23,D$15),0),0) -> 11765.706
G28: 23 | H28: =IFERROR(IFERROR(-PPMT(D$22,((23-1)*12)+1,D$23,D$15),0)+IFERROR(-PPMT(D$22,((23-1)*12)+2,D$23,D$15),0)+IFERROR(-PPMT(D$22,((23-1)*12)+3,D$23,D$15),0)+IFERROR(-PPMT(D$22,((23-1)*12)+4,D$23,D$15),0)+IFERROR(-PPMT(D$22,((23-1)*12)+5,D$23,D$15),0)+IFERROR(-PPMT(D$22,((23-1)*12)+6,D$23,D$15),0)+IFERROR(-PPMT(D$22,((23-1)*12)+7,D$23,D$15),0)+IFERROR(-PPMT(D$22,((23-1)*12)+8,D$23,D$15),0)+IFERROR(-PPMT(D$22,((23-1)*12)+9,D$23,D$15),0)+IFERROR(-PPMT(D$22,((23-1)*12)+10,D$23,D$15),0)+IFERROR(-PPMT(D$22,((23-1)*12)+11,D$23,D$15),0)+IFERROR(-PPMT(D$22,((23-1)*12)+12,D$23,D$15),0),0) -> 71410.675 | I28: =IFERROR(IFERROR(-IPMT(D$22,((23-1)*12)+1,D$23,D$15),0)+IFERROR(-IPMT(D$22,((23-1)*12)+2,D$23,D$15),0)+IFERROR(-IPMT(D$22,((23-1)*12)+3,D$23,D$15),0)+IFERROR(-IPMT(D$22,((23-1)*12)+4,D$23,D$15),0)+IFERROR(-IPMT(D$22,((23-1)*12)+5,D$23,D$15),0)+IFERROR(-IPMT(D$22,((23-1)*12)+6,D$23,D$15),0)+IFERROR(-IPMT(D$22,((23-1)*12)+7,D$23,D$15),0)+IFERROR(-IPMT(D$22,((23-1)*12)+8,D$23,D$15),0)+IFERROR(-IPMT(D$22,((23-1)*12)+9,D$23,D$15),0)+IFERROR(-IPMT(D$22,((23-1)*12)+10,D$23,D$15),0)+IFERROR(-IPMT(D$22,((23-1)*12)+11,D$23,D$15),0)+IFERROR(-IPMT(D$22,((23-1)*12)+12,D$23,D$15),0),0) -> 8629.2021
C29: ④ TOTAL CAPITAL DEPLOYED (Your Cash Out-of-Pocket) | G29: 24 | H29: =IFERROR(IFERROR(-PPMT(D$22,((24-1)*12)+1,D$23,D$15),0)+IFERROR(-PPMT(D$22,((24-1)*12)+2,D$23,D$15),0)+IFERROR(-PPMT(D$22,((24-1)*12)+3,D$23,D$15),0)+IFERROR(-PPMT(D$22,((24-1)*12)+4,D$23,D$15),0)+IFERROR(-PPMT(D$22,((24-1)*12)+5,D$23,D$15),0)+IFERROR(-PPMT(D$22,((24-1)*12)+6,D$23,D$15),0)+IFERROR(-PPMT(D$22,((24-1)*12)+7,D$23,D$15),0)+IFERROR(-PPMT(D$22,((24-1)*12)+8,D$23,D$15),0)+IFERROR(-PPMT(D$22,((24-1)*12)+9,D$23,D$15),0)+IFERROR(-PPMT(D$22,((24-1)*12)+10,D$23,D$15),0)+IFERROR(-PPMT(D$22,((24-1)*12)+11,D$23,D$15),0)+IFERROR(-PPMT(D$22,((24-1)*12)+12,D$23,D$15),0),0) -> 74691.269 | I29: =IFERROR(IFERROR(-IPMT(D$22,((24-1)*12)+1,D$23,D$15),0)+IFERROR(-IPMT(D$22,((24-1)*12)+2,D$23,D$15),0)+IFERROR(-IPMT(D$22,((24-1)*12)+3,D$23,D$15),0)+IFERROR(-IPMT(D$22,((24-1)*12)+4,D$23,D$15),0)+IFERROR(-IPMT(D$22,((24-1)*12)+5,D$23,D$15),0)+IFERROR(-IPMT(D$22,((24-1)*12)+6,D$23,D$15),0)+IFERROR(-IPMT(D$22,((24-1)*12)+7,D$23,D$15),0)+IFERROR(-IPMT(D$22,((24-1)*12)+8,D$23,D$15),0)+IFERROR(-IPMT(D$22,((24-1)*12)+9,D$23,D$15),0)+IFERROR(-IPMT(D$22,((24-1)*12)+10,D$23,D$15),0)+IFERROR(-IPMT(D$22,((24-1)*12)+11,D$23,D$15),0)+IFERROR(-IPMT(D$22,((24-1)*12)+12,D$23,D$15),0),0) -> 5348.6082
C30: Cash Deployed at Purchase | D30: =D14+D10+D18+D19 -> 396290 | E30: =E7+E10 -> 1560000 | G30: 25 | H30: =IFERROR(IFERROR(-PPMT(D$22,((25-1)*12)+1,D$23,D$15),0)+IFERROR(-PPMT(D$22,((25-1)*12)+2,D$23,D$15),0)+IFERROR(-PPMT(D$22,((25-1)*12)+3,D$23,D$15),0)+IFERROR(-PPMT(D$22,((25-1)*12)+4,D$23,D$15),0)+IFERROR(-PPMT(D$22,((25-1)*12)+5,D$23,D$15),0)+IFERROR(-PPMT(D$22,((25-1)*12)+6,D$23,D$15),0)+IFERROR(-PPMT(D$22,((25-1)*12)+7,D$23,D$15),0)+IFERROR(-PPMT(D$22,((25-1)*12)+8,D$23,D$15),0)+IFERROR(-PPMT(D$22,((25-1)*12)+9,D$23,D$15),0)+IFERROR(-PPMT(D$22,((25-1)*12)+10,D$23,D$15),0)+IFERROR(-PPMT(D$22,((25-1)*12)+11,D$23,D$15),0)+IFERROR(-PPMT(D$22,((25-1)*12)+12,D$23,D$15),0),0) -> 78122.572 | I30: =IFERROR(IFERROR(-IPMT(D$22,((25-1)*12)+1,D$23,D$15),0)+IFERROR(-IPMT(D$22,((25-1)*12)+2,D$23,D$15),0)+IFERROR(-IPMT(D$22,((25-1)*12)+3,D$23,D$15),0)+IFERROR(-IPMT(D$22,((25-1)*12)+4,D$23,D$15),0)+IFERROR(-IPMT(D$22,((25-1)*12)+5,D$23,D$15),0)+IFERROR(-IPMT(D$22,((25-1)*12)+6,D$23,D$15),0)+IFERROR(-IPMT(D$22,((25-1)*12)+7,D$23,D$15),0)+IFERROR(-IPMT(D$22,((25-1)*12)+8,D$23,D$15),0)+IFERROR(-IPMT(D$22,((25-1)*12)+9,D$23,D$15),0)+IFERROR(-IPMT(D$22,((25-1)*12)+10,D$23,D$15),0)+IFERROR(-IPMT(D$22,((25-1)*12)+11,D$23,D$15),0)+IFERROR(-IPMT(D$22,((25-1)*12)+12,D$23,D$15),0),0) -> 1917.3044
B31: C1 | C31: Total Cash Invested (incl. all mortgage pmts) | D31: =D30+(D25*D17) -> 2397286.9 | E31: =E30 -> 1560000 | G31: TOTAL | H31: =SUM(H6:H30) -> 1200000 | I31: =SUM(I6:I30) -> 800996.92
C33: ⑤ ANNUAL CASH FLOW COMPARISON | G33: 📘 GUIDE — How to Read the KPIs
C34: Gross Annual Rent | D34: =D8 -> 110000 | E34: =E8 -> 110000 | G34: Cash-on-Cash (CoC) | H34: Net cash flow ÷ actual cash deployed. Best measure of leverage benefit.
C35: Less: Vacancy (5%) | D35: =D8*0.05 -> 5500 | E35: =E8*0.05 -> 5500 | G35: ROE | H35: Cash flow ÷ equity (down payment). Higher with mortgage = leverage working.
C36: Less: Holding Costs | D36: =D9 -> 35000 | E36: =E9 -> 35000 | G36: DSCR | H36: >1.25x = healthy. <1.0x = rent doesn't cover mortgage — danger zone.
C37: Less: Annual Mortgage Payment | D37: =D25 -> 80039.877 | E37: =0 -> 0 | G37: Leverage Multiplier | H37: ROE ÷ Net Yield. >1x means financing amplifies your return.
B38: CF1 | C38: NET ANNUAL CASH FLOW | D38: =D8-D35-D9-D25 -> -10539.877 | E38: =E8-E35-E9 -> 69500 | G38: Break-even Occ. | H38: % occupancy needed just to cover costs. Lower = safer investment.
B39: CF2 | C39: Monthly Cash Flow | D39: =D38/12 -> -878.32307 | E39: =E38/12 -> 5791.6667 | G39: When mortgage wins | H39: Low rates + high appreciation = leverage magnifies total return.
G40: When cash wins | H40: High rates, flat market, or you want guaranteed positive cash flow.
C41: ⑥ KEY KPIs — MORTGAGE vs CASH (The Verdict)
B42: K1 | C42: Gross Rental Yield (%) | D42: =IFERROR(D8/D7,0) -> 0.073333333 | E42: =IFERROR(E8/E7,0) -> 0.073333333
...

Sheet 📈 Cash Flow Projection
A1: 📈 CASH FLOW PROJECTION — 10 YEAR ANALYSIS
A2: Select a property from the comparison sheet · Adjust rent growth and appreciation for scenario analysis
B4: SCENARIO INPUTS
B5: Initial Property Value (AED) | C5: 1200000 | E5: Annual Rent (AED) | F5: 90000 | H5: Appreciation %/yr | I5: 0.05
B6: Annual Holding Costs (AED) | C6: 30000 | E6: Rent Growth %/yr | F6: 0.03 | H6: Vacancy Rate | I6: 0.05
B8: 10-YEAR PROJECTION
B9: METRIC | C9: Year 1 | D9: Year 2 | E9: Year 3 | F9: Year 4 | G9: Year 5 | H9: Year 6 | I9: Year 7 | J9: Year 8 | K9: Year 9 | L9: Year 10
B10: Property Value (AED) | C10: =$C$5*(1+$I$5) -> 1260000 | D10: =$C10*(1+$I$5) -> 1323000 | E10: =$D10*(1+$I$5) -> 1389150 | F10: =$E10*(1+$I$5) -> 1458607.5 | G10: =$F10*(1+$I$5) -> 1531537.9 | H10: =$G10*(1+$I$5) -> 1608114.8 | I10: =$H10*(1+$I$5) -> 1688520.5 | J10: =$I10*(1+$I$5) -> 1772946.5 | K10: =$J10*(1+$I$5) -> 1861593.9 | L10: =$K10*(1+$I$5) -> 1954673.6
B11: Gross Rent (AED) | C11: =$F$5 -> 90000 | D11: =$C11*(1+$F$6) -> 92700 | E11: =$D11*(1+$F$6) -> 95481 | F11: =$E11*(1+$F$6) -> 98345.43 | G11: =$F11*(1+$F$6) -> 101295.79 | H11: =$G11*(1+$F$6) -> 104334.67 | I11: =$H11*(1+$F$6) -> 107464.71 | J11: =$I11*(1+$F$6) -> 110688.65 | K11: =$J11*(1+$F$6) -> 114009.31 | L11: =$K11*(1+$F$6) -> 117429.59
B12: Effective Rent (AED) | C12: =$C11*(1-$I$6) -> 85500 | D12: =$D11*(1-$I$6) -> 88065 | E12: =$E11*(1-$I$6) -> 90706.95 | F12: =$F11*(1-$I$6) -> 93428.159 | G12: =$G11*(1-$I$6) -> 96231.003 | H12: =$H11*(1-$I$6) -> 99117.933 | I12: =$I11*(1-$I$6) -> 102091.47 | J12: =$J11*(1-$I$6) -> 105154.22 | K12: =$K11*(1-$I$6) -> 108308.84 | L12: =$L11*(1-$I$6) -> 111558.11
B13: Holding Costs (AED) | C13: =$C$6 -> 30000 | D13: =$C13*1.02 -> 30600 | E13: =$D13*1.02 -> 31212 | F13: =$E13*1.02 -> 31836.24 | G13: =$F13*1.02 -> 32472.965 | H13: =$G13*1.02 -> 33122.424 | I13: =$H13*1.02 -> 33784.873 | J13: =$I13*1.02 -> 34460.57 | K13: =$J13*1.02 -> 35149.781 | L13: =$K13*1.02 -> 35852.777
B14: Net Cash Flow (AED) | C14: =$C12-$C13 -> 55500 | D14: =$D12-$D13 -> 57465 | E14: =$E12-$E13 -> 59494.95 | F14: =$F12-$F13 -> 61591.918 | G14: =$G12-$G13 -> 63758.038 | H14: =$H12-$H13 -> 65995.509 | I14: =$I12-$I13 -> 68306.599 | J14: =$J12-$J13 -> 70693.645 | K14: =$K12-$K13 -> 73159.061 | L14: =$L12-$L13 -> 75705.33
B15: Cumulative Cash Flow | C15: =$C14 -> 55500 | D15: =$C15+$D14 -> 112965 | E15: =$D15+$E14 -> 172459.95 | F15: =$E15+$F14 -> 234051.87 | G15: =$F15+$G14 -> 297809.91 | H15: =$G15+$H14 -> 363805.42 | I15: =$H15+$I14 -> 432112.01 | J15: =$I15+$J14 -> 502805.66 | K15: =$J15+$K14 -> 575964.72 | L15: =$K15+$L14 -> 651670.05
B16: Capital Gain (AED) | C16: =$C10-$C$5 -> 60000 | D16: =$D10-$C$5 -> 123000 | E16: =$E10-$C$5 -> 189150 | F16: =$F10-$C$5 -> 258607.5 | G16: =$G10-$C$5 -> 331537.88 | H16: =$H10-$C$5 -> 408114.77 | I16: =$I10-$C$5 -> 488520.51 | J16: =$J10-$C$5 -> 572946.53 | K16: =$K10-$C$5 -> 661593.86 | L16: =$L10-$C$5 -> 754673.55
B17: Total Wealth (AED) | C17: =$C15+$C16 -> 115500 | D17: =$D15+$D16 -> 235965 | E17: =$E15+$E16 -> 361609.95 | F17: =$F15+$F16 -> 492659.37 | G17: =$G15+$G16 -> 629347.78 | H17: =$H15+$H16 -> 771920.18 | I17: =$I15+$I16 -> 920632.52 | J17: =$J15+$J16 -> 1075752.2 | K17: =$K15+$K16 -> 1237558.6 | L17: =$L15+$L16 -> 1406343.6
B18: ROI (annual) | C18: =IFERROR($C14/$C$5,0) -> 0.04625 | D18: =IFERROR($D14/$C$5,0) -> 0.0478875 | E18: =IFERROR($E14/$C$5,0) -> 0.049579125 | F18: =IFERROR($F14/$C$5,0) -> 0.051326599 | G18: =IFERROR($G14/$C$5,0) -> 0.053131699 | H18: =IFERROR($H14/$C$5,0) -> 0.054996258 | I18: =IFERROR($I14/$C$5,0) -> 0.056922166 | J18: =IFERROR($J14/$C$5,0) -> 0.058911371 | K18: =IFERROR($K14/$C$5,0) -> 0.060965884 | L18: =IFERROR($L14/$C$5,0) -> 0.063087775
B19: Cumulative ROI | C19: =IFERROR($C17/$C$5,0) -> 0.09625 | D19: =IFERROR($D17/$C$5,0) -> 0.1966375 | E19: =IFERROR($E17/$C$5,0) -> 0.30134163 | F19: =IFERROR($F17/$C$5,0) -> 0.41054947 | G19: =IFERROR($G17/$C$5,0) -> 0.52445648 | H19: =IFERROR($H17/$C$5,0) -> 0.64326682 | I19: =IFERROR($I17/$C$5,0) -> 0.76719377 | J19: =IFERROR($J17/$C$5,0) -> 0.89646016 | K19: =IFERROR($K17/$C$5,0) -> 1.0312988 | L19: =IFERROR($L17/$C$5,0) -> 1.171953

Sheet 📋 DLD Fee Guide
A1: 📋 DUBAI LAND DEPARTMENT — FEE GUIDE & REFERENCE
B3: FEE TYPE | C3: AMOUNT | D3: NOTES
B4: DLD Transfer Fee | C4: 4% of purchase price | D4: Mandatory for all property transfers. Paid to Dubai Land Department.
B5: Trustee Office Fee | C5: AED 4,000 (residential) / AED 10,000 (commercial) | D5: Payable to the Trustee's office handling the transfer.
B6: NOC Certificate | C6: AED 500 – AED 5,000 | D6: No Objection Certificate from developer. Varies by developer.
B7: Real Estate Agent Commission | C7: 2% of purchase price | D7: Buyer typically pays 2%; sometimes negotiable.
B8: Mortgage Registration Fee | C8: 0.25% of loan amount + AED 290 | D8: Applicable only when financing through a bank.
B9: Property Valuation Fee | C9: AED 2,500 – AED 3,500 | D9: Required by banks for mortgage applications.
B10: Title Deed Registration Fee | C10: AED 580 (e-Title) | D10: Electronic title deed issuance fee.
B11: Service Charges (annual) | C11: AED 12 – AED 35 per sq ft | D11: Varies by community. Paid to RERA-regulated OA.
B12: Property Management | C12: 5% – 10% of annual rent | D12: If using a property management company.
B13: DEWA Security Deposit | C13: AED 2,000 (apts) / AED 4,000 (villas) | D13: Refundable deposit for electricity & water.
B14: Ejari Registration | C14: AED 220 | D14: Mandatory tenancy contract registration fee.

Sheet 📊 KPI Dashboard
A1: 📊 PROPERTY COMPARISON DASHBOARD
B3: KPI | C3: Property 1 | D3: Property 2 | E3: Property 3 | F3: Property 4 | G3: Property 5
B4: Property Name | C4: ='🏠 Property Comparison'!E6 -> Property 2 | D4: ='🏠 Property Comparison'!F6 -> Property 3 | E4: ='🏠 Property Comparison'!G6 -> Property 4 | F4: ='🏠 Property Comparison'!H6 -> Property 5
B5: Purchase Price | C5: ='🏠 Property Comparison'!E11 -> 2500000 | D5: ='🏠 Property Comparison'!F11 -> 900000 | E5: ='🏠 Property Comparison'!G11 -> 6500000 | F5: ='🏠 Property Comparison'!H11 -> 1800000
B6: Net Rental Yield | C6: ='🏠 Property Comparison'!E47 -> 0.048608 | D6: ='🏠 Property Comparison'!F47 -> 0.048823111 | E6: ='🏠 Property Comparison'!G47 -> 0.047556923 | F6: ='🏠 Property Comparison'!H47 -> 0.047791111
B7: ROI | C7: ='🏠 Property Comparison'!E48 -> 0.04466826 | D7: ='🏠 Property Comparison'!F48 -> 0.044632605 | E7: ='🏠 Property Comparison'!G48 -> 0.043534962 | F7: ='🏠 Property Comparison'!H48 -> 0.043700279
B8: ROE | C8: ='🏠 Property Comparison'!E49 -> 0.048608 | D8: ='🏠 Property Comparison'!F49 -> 0.048823111 | E8: ='🏠 Property Comparison'!G49 -> 0.047556923 | F8: ='🏠 Property Comparison'!H49 -> 0.047791111
B9: Annual Cash Flow | C9: ='🏠 Property Comparison'!E50 -> 121520 | D9: ='🏠 Property Comparison'!F50 -> 43940.8 | E9: ='🏠 Property Comparison'!G50 -> 309120 | F9: ='🏠 Property Comparison'!H50 -> 86024
B10: Payback (yrs) | C10: ='🏠 Property Comparison'!E52 -> 22.387261 | D10: ='🏠 Property Comparison'!F52 -> 22.405145 | E10: ='🏠 Property Comparison'!G52 -> 22.970044 | F10: ='🏠 Property Comparison'!H52 -> 22.883149
B11: Composite Score | C11: ='🏠 Property Comparison'!E66 -> 4.9310504 | D11: ='🏠 Property Comparison'!F66 -> 5.1382287 | E11: ='🏠 Property Comparison'!G66 -> 4.6436754 | F11: ='🏠 Property Comparison'!H66 -> 4.8596556
B12: Rank | C12: ='🏠 Property Comparison'!E67 -> 2 | D12: ='🏠 Property Comparison'!F67 -> 1 | E12: ='🏠 Property Comparison'!G67 -> 5 | F12: ='🏠 Property Comparison'!H67 -> 3
B15: ROI Comparison Chart ↓
B16: ROI (%) | C16: ='🏠 Property Comparison'!E48 -> 0.04466826 | D16: ='🏠 Property Comparison'!F48 -> 0.044632605 | E16: ='🏠 Property Comparison'!G48 -> 0.043534962 | F16: ='🏠 Property Comparison'!H48 -> 0.043700279
B17: Net Yield (%) | C17: ='🏠 Property Comparison'!E47 -> 0.048608 | D17: ='🏠 Property Comparison'!F47 -> 0.048823111 | E17: ='🏠 Property Comparison'!G47 -> 0.047556923 | F17: ='🏠 Property Comparison'!H47 -> 0.047791111
